cleaINFO:albumentations.check_version:A new version of Albumentations is available: 1.4.11 (you have 1.4.10). Upgrade using: pip install --upgrade albumentations
Namespace(batch=64, dataset='datasets/rosbotxl_data', epochs=100, log_interval=50, lr=0.0001, noisevar=15, robustification=True)
Found data_cleaned.csv in datasets/rosbotxl_data/003
Found data_cleaned.csv in datasets/rosbotxl_data/002
Finished intaking image paths!
Retrieving output distribution....
Moments of distribution: {'shape': (2456,), 'mean': -0.00856331030228433, 'median': 0.0, 'var': 0.022344652883072448, 'skew': -0.22090519333532943, 'kurtosis': 11.833545883752118, 'max': 1.0, 'min': -1.0}
Total samples: 2456
time to load dataset: 2.1325137615203857
iteration='DAVE2v3-2560x720-lr0.0001-100epoch-64batch-lossMSE-2Ksamples-INDUSTRIALandHIROCHIandUTAH-noiseflipblur'
device=device(type='cuda')
Traceback (most recent call last):
  File "/u/ezj2hu/ROSbot_data_collection/.venv/lib/python3.8/site-packages/pandas/core/indexes/base.py", line 3653, in get_loc
    return self._engine.get_loc(casted_key)
  File "pandas/_libs/index.pyx", line 147, in pandas._libs.index.IndexEngine.get_loc
  File "pandas/_libs/index.pyx", line 176, in pandas._libs.index.IndexEngine.get_loc
  File "pandas/_libs/hashtable_class_helper.pxi", line 7080, in pandas._libs.hashtable.PyObjectHashTable.get_item
  File "pandas/_libs/hashtable_class_helper.pxi", line 7088, in pandas._libs.hashtable.PyObjectHashTable.get_item
KeyError: 'image'

The above exception was the direct cause of the following exception:

Traceback (most recent call last):
  File "training/Zach_train_DAVE2.py", line 161, in <module>
    main()
  File "training/Zach_train_DAVE2.py", line 88, in main
    for i, batch in enumerate(trainloader, 0):
  File "/u/ezj2hu/ROSbot_data_collection/.venv/lib/python3.8/site-packages/torch/utils/data/dataloader.py", line 631, in __next__
    data = self._next_data()
  File "/u/ezj2hu/ROSbot_data_collection/.venv/lib/python3.8/site-packages/torch/utils/data/dataloader.py", line 675, in _next_data
    data = self._dataset_fetcher.fetch(index)  # may raise StopIteration
  File "/u/ezj2hu/ROSbot_data_collection/.venv/lib/python3.8/site-packages/torch/utils/data/_utils/fetch.py", line 51, in fetch
    data = [self.dataset[idx] for idx in possibly_batched_index]
  File "/u/ezj2hu/ROSbot_data_collection/.venv/lib/python3.8/site-packages/torch/utils/data/_utils/fetch.py", line 51, in <listcomp>
    data = [self.dataset[idx] for idx in possibly_batched_index]
  File "/u/ezj2hu/ROSbot_data_collection/training/Zach_DatasetGenerator.py", line 272, in __getitem__
    df_index = df.index[df['image'] == img_name.name]
  File "/u/ezj2hu/ROSbot_data_collection/.venv/lib/python3.8/site-packages/pandas/core/frame.py", line 3761, in __getitem__
    indexer = self.columns.get_loc(key)
  File "/u/ezj2hu/ROSbot_data_collection/.venv/lib/python3.8/site-packages/pandas/core/indexes/base.py", line 3655, in get_loc
    raise KeyError(key) from err
KeyError: 'image'
